<?xml version="1.0"?>
<robot xmlns:xacro="http://www.ros.org/wiki/xacro">
    <xacro:macro  name="wheel" params="prefix reflect base_width wheel_radius *axis">
        <xacro:property name="wheel_len" value="0.1" />
        <xacro:property name="wheel_mass" value="0.5" />
        <link name="${prefix}_wheel">
            <visual>
                <geometry>
                    <cylinder radius="${wheel_radius}" length="${wheel_len}"/>
                </geometry>
                <origin xyz="0 0 0"/>
                <material name="white"/>
            </visual>
            <collision>
                <geometry>
                    <cylinder radius="${wheel_radius}" length="${wheel_len}"/>
                </geometry>
                <origin xyz="0 0 0"/>
            </collision>
            <inertial>
                <mass value="${wheel_mass}"/>
                <inertia
                    ixx="${1/12*wheel_mass*(3*(wheel_radius*wheel_radius)+wheel_len*wheel_len)}" 
                    ixy="0.0" 
                    ixz="0.0" 
                    iyy="${1/12*wheel_mass*(3*wheel_radius*wheel_radius+wheel_len*wheel_len)}" 
                    iyz="0.0" 
                    izz="${1/12*wheel_mass*(wheel_radius*wheel_radius)}"/>  
            </inertial>
        </link>
        <joint name="base_to_${prefix}_wheel" type="continuous">
            <parent link="base_link"/>
            <child link="${prefix}_wheel"/>
            <origin xyz="0 ${reflect*(base_width+wheel_len/2)} 0" rpy="${-pi/2} 0 0" />
            <xacro:insert_block name="axis" />
        </joint>
    </xacro:macro>
</robot>